Workbook

Sheet Deals
A1: deal_type | B1: date | C1: company | D1: amount_usd | E1: stage | F1: customer_type | G1: sector | H1: sub_segment | I1: use_case | J1: country | K1: region | L1: lead_investors | M1: founder_notes | N1: source_url | P1: amt_for_median (helper — do not edit)
A2: funding | B2: 2026-06-23 | C2: ExampleAI | D2: 12000000 | E2: Series A | F2: B2B | G2: AI | H2: legal-ai | I2: Automates contract review for in-house legal teams | J2: USA | K2: North America | L2: Acme Ventures | M2: Repeat founder ex-BigLaw | N2: https://www.finsmes.com/example | P2: =IF(AND($A2="funding",ISNUMBER($D2)),$D2,"") -> 12000000
A3: funding | B3: 2026-06-24 | C3: PaySeed | D3: 2500000 | E3: Seed | F3: B2B | G3: Fintech | H3: payments-infra | I3: Embedded payments API for marketplaces | J3: UK | K3: Europe | L3: Seed Capital LLP | M3: First-time technical founder | N3: https://techcrunch.com/example | P3: =IF(AND($A3="funding",ISNUMBER($D3)),$D3,"") -> 2500000
A4: acquisition | B4: 2026-06-25 | C4: DataCo | E4: Acquisition | F4: B2B | G4: Data | H4: analytics | I4: Acquired by BigCorp for analytics stack | J4: Germany | K4: Europe | M4: n/a | N4: https://www.finsmes.com/example2 | P4: =IF(AND($A4="funding",ISNUMBER($D4)),$D4,"")
P5: =IF(AND($A5="funding",ISNUMBER($D5)),$D5,"")
P6: =IF(AND($A6="funding",ISNUMBER($D6)),$D6,"")
P7: =IF(AND($A7="funding",ISNUMBER($D7)),$D7,"")
P8: =IF(AND($A8="funding",ISNUMBER($D8)),$D8,"")
P9: =IF(AND($A9="funding",ISNUMBER($D9)),$D9,"")
P10: =IF(AND($A10="funding",ISNUMBER($D10)),$D10,"")
P11: =IF(AND($A11="funding",ISNUMBER($D11)),$D11,"")
P12: =IF(AND($A12="funding",ISNUMBER($D12)),$D12,"")
P13: =IF(AND($A13="funding",ISNUMBER($D13)),$D13,"")
P14: =IF(AND($A14="funding",ISNUMBER($D14)),$D14,"")
P15: =IF(AND($A15="funding",ISNUMBER($D15)),$D15,"")
P16: =IF(AND($A16="funding",ISNUMBER($D16)),$D16,"")
... P501: =IF(AND($A501="funding",ISNUMBER($D501)),$D501,"")

Sheet Metrics
A1: Funding Digest — Metrics
A2: Numbers update automatically as you fill in the Deals tab. Only the yellow cell needs typing.
A4: HEADLINE
A5: Funding rounds | B5: =COUNTIF(Deals!$A$2:$A$501,"funding") -> 2
A6: Acquisitions | B6: =COUNTIF(Deals!$A$2:$A$501,"acquisition") -> 1
A7: Rounds w/ undisclosed amount | B7: =COUNTIFS(Deals!$A$2:$A$501,"funding",Deals!$D$2:$D$501,"") -> 0
A8: Total raised ($) | B8: =SUMIFS(Deals!$D$2:$D$501,Deals!$A$2:$A$501,"funding") -> 14500000
A9: Median round ($) | B9: =IF(COUNT(Deals!$P$2:$P$501)=0,"n/a",MEDIAN(Deals!$P$2:$P$501)) -> 7250000
A10: Prior-period total ($) — INPUT | B10: 0
A11: Growth vs prior | B11: =IF(OR($B$10="",$B$10=0),"n/a",($B$8-$B$10)/$B$10) -> n/a
A13: STAGE SPLIT | B13: Deals | C13: Dollars ($)
A14: Pre-seed | B14: =COUNTIFS(Deals!$A$2:$A$501,"funding",Deals!$E$2:$E$501,$A14) -> 0 | C14: =SUMIFS(Deals!$D$2:$D$501,Deals!$A$2:$A$501,"funding",Deals!$E$2:$E$501,$A14) -> 0
A15: Seed | B15: =COUNTIFS(Deals!$A$2:$A$501,"funding",Deals!$E$2:$E$501,$A15) -> 1 | C15: =SUMIFS(Deals!$D$2:$D$501,Deals!$A$2:$A$501,"funding",Deals!$E$2:$E$501,$A15) -> 2500000
A16: Series A | B16: =COUNTIFS(Deals!$A$2:$A$501,"funding",Deals!$E$2:$E$501,$A16) -> 1 | C16: =SUMIFS(Deals!$D$2:$D$501,Deals!$A$2:$A$501,"funding",Deals!$E$2:$E$501,$A16) -> 12000000
A17: Series B | B17: =COUNTIFS(Deals!$A$2:$A$501,"funding",Deals!$E$2:$E$501,$A17) -> 0 | C17: =SUMIFS(Deals!$D$2:$D$501,Deals!$A$2:$A$501,"funding",Deals!$E$2:$E$501,$A17) -> 0
A18: Series C | B18: =COUNTIFS(Deals!$A$2:$A$501,"funding",Deals!$E$2:$E$501,$A18) -> 0 | C18: =SUMIFS(Deals!$D$2:$D$501,Deals!$A$2:$A$501,"funding",Deals!$E$2:$E$501,$A18) -> 0
A19: Growth/Late | B19: =COUNTIFS(Deals!$A$2:$A$501,"funding",Deals!$E$2:$E$501,$A19) -> 0 | C19: =SUMIFS(Deals!$D$2:$D$501,Deals!$A$2:$A$501,"funding",Deals!$E$2:$E$501,$A19) -> 0
A20: Other | B20: =COUNTIFS(Deals!$A$2:$A$501,"funding",Deals!$E$2:$E$501,$A20) -> 0 | C20: =SUMIFS(Deals!$D$2:$D$501,Deals!$A$2:$A$501,"funding",Deals!$E$2:$E$501,$A20) -> 0
A21: Total (check vs headline) | B21: =SUM(B14:B20) -> 2 | C21: =SUM(C14:C20) -> 14500000
A23: CUSTOMER TYPE | B23: Deals
A24: B2B | B24: =COUNTIFS(Deals!$A$2:$A$501,"funding",Deals!$F$2:$F$501,$A24) -> 2
A25: B2C | B25: =COUNTIFS(Deals!$A$2:$A$501,"funding",Deals!$F$2:$F$501,$A25) -> 0
A26: B2G | B26: =COUNTIFS(Deals!$A$2:$A$501,"funding",Deals!$F$2:$F$501,$A26) -> 0
A27: B2B2C | B27: =COUNTIFS(Deals!$A$2:$A$501,"funding",Deals!$F$2:$F$501,$A27) -> 0
A29: SECTOR (rename rows to match your tags) | B29: Deals | C29: Dollars ($)
A30: AI | B30: =COUNTIFS(Deals!$A$2:$A$501,"funding",Deals!$G$2:$G$501,$A30) -> 1 | C30: =SUMIFS(Deals!$D$2:$D$501,Deals!$A$2:$A$501,"funding",Deals!$G$2:$G$501,$A30) -> 12000000
A31: Fintech | B31: =COUNTIFS(Deals!$A$2:$A$501,"funding",Deals!$G$2:$G$501,$A31) -> 1 | C31: =SUMIFS(Deals!$D$2:$D$501,Deals!$A$2:$A$501,"funding",Deals!$G$2:$G$501,$A31) -> 2500000
A32: Healthcare | B32: =COUNTIFS(Deals!$A$2:$A$501,"funding",Deals!$G$2:$G$501,$A32) -> 0 | C32: =SUMIFS(Deals!$D$2:$D$501,Deals!$A$2:$A$501,"funding",Deals!$G$2:$G$501,$A32) -> 0
A33: Biotech | B33: =COUNTIFS(Deals!$A$2:$A$501,"funding",Deals!$G$2:$G$501,$A33) -> 0 | C33: =SUMIFS(Deals!$D$2:$D$501,Deals!$A$2:$A$501,"funding",Deals!$G$2:$G$501,$A33) -> 0
A34: Climate/Energy | B34: =COUNTIFS(Deals!$A$2:$A$501,"funding",Deals!$G$2:$G$501,$A34) -> 0 | C34: =SUMIFS(Deals!$D$2:$D$501,Deals!$A$2:$A$501,"funding",Deals!$G$2:$G$501,$A34) -> 0
A35: Enterprise SaaS | B35: =COUNTIFS(Deals!$A$2:$A$501,"funding",Deals!$G$2:$G$501,$A35) -> 0 | C35: =SUMIFS(Deals!$D$2:$D$501,Deals!$A$2:$A$501,"funding",Deals!$G$2:$G$501,$A35) -> 0
A36: Dev Tools | B36: =COUNTIFS(Deals!$A$2:$A$501,"funding",Deals!$G$2:$G$501,$A36) -> 0 | C36: =SUMIFS(Deals!$D$2:$D$501,Deals!$A$2:$A$501,"funding",Deals!$G$2:$G$501,$A36) -> 0
A37: Security | B37: =COUNTIFS(Deals!$A$2:$A$501,"funding",Deals!$G$2:$G$501,$A37) -> 0 | C37: =SUMIFS(Deals!$D$2:$D$501,Deals!$A$2:$A$501,"funding",Deals!$G$2:$G$501,$A37) -> 0
A38: Data/Infra | B38: =COUNTIFS(Deals!$A$2:$A$501,"funding",Deals!$G$2:$G$501,$A38) -> 0 | C38: =SUMIFS(Deals!$D$2:$D$501,Deals!$A$2:$A$501,"funding",Deals!$G$2:$G$501,$A38) -> 0
A39: Consumer | B39: =COUNTIFS(Deals!$A$2:$A$501,"funding",Deals!$G$2:$G$501,$A39) -> 0 | C39: =SUMIFS(Deals!$D$2:$D$501,Deals!$A$2:$A$501,"funding",Deals!$G$2:$G$501,$A39) -> 0
A40: Robotics/Hardware | B40: =COUNTIFS(Deals!$A$2:$A$501,"funding",Deals!$G$2:$G$501,$A40) -> 0 | C40: =SUMIFS(Deals!$D$2:$D$501,Deals!$A$2:$A$501,"funding",Deals!$G$2:$G$501,$A40) -> 0
A41: Other | B41: =COUNTIFS(Deals!$A$2:$A$501,"funding",Deals!$G$2:$G$501,$A41) -> 0 | C41: =SUMIFS(Deals!$D$2:$D$501,Deals!$A$2:$A$501,"funding",Deals!$G$2:$G$501,$A41) -> 0
A43: REGION | B43: Deals | C43: Dollars ($)
A44: North America | B44: =COUNTIFS(Deals!$A$2:$A$501,"funding",Deals!$K$2:$K$501,$A44) -> 1 | C44: =SUMIFS(Deals!$D$2:$D$501,Deals!$A$2:$A$501,"funding",Deals!$K$2:$K$501,$A44) -> 12000000
A45: Europe | B45: =COUNTIFS(Deals!$A$2:$A$501,"funding",Deals!$K$2:$K$501,$A45) -> 1 | C45: =SUMIFS(Deals!$D$2:$D$501,Deals!$A$2:$A$501,"funding",Deals!$K$2:$K$501,$A45) -> 2500000
...
